2025-10-19 02:59:24,125 DEBUG    root            Loaded Command Group: ['gcloud', 'auth']
2025-10-19 02:59:24,127 DEBUG    root            Loaded Command Group: ['gcloud', 'auth', 'list']
2025-10-19 02:59:24,129 DEBUG    root            Running [gcloud.auth.list] with arguments: []
2025-10-19 02:59:24,144 DEBUG    root            Chosen display Format:    table[title='Credentialed Accounts'](
        status.yesno(yes='*', no=''):label=ACTIVE,
        account
    )
2025-10-19 02:59:24,145 INFO     root            Display format: "    table[title='Credentialed Accounts'](
        status.yesno(yes='*', no=''):label=ACTIVE,
        account
    )"
2025-10-19 02:59:24,145 INFO     ___FILE_ONLY___ 
No credentialed accounts.

To login, run:
  $ gcloud auth login `ACCOUNT`


2025-10-19 02:59:24,292 DEBUG    root            Checking for updates...
2025-10-19 02:59:24,346 DEBUG    urllib3.connectionpool Starting new HTTPS connection (1): dl.google.com:443
2025-10-19 02:59:24,348 DEBUG    root            Failed to perform update check.
Traceback (most recent call last):
  File "/usr/local/Caskroom/gcloud-cli/543.0.0/google-cloud-sdk/lib/third_party/urllib3/connection.py", line 198, in _new_conn
    sock = connection.create_connection(
  File "/usr/local/Caskroom/gcloud-cli/543.0.0/google-cloud-sdk/lib/third_party/urllib3/util/connection.py", line 62, in create_connection
    for res in socket.getaddrinfo(host, port, family, socket.SOCK_STREAM):
  File "/Library/Developer/CommandLineTools/Library/Frameworks/Python3.framework/Versions/3.9/lib/python3.9/socket.py", line 953, in getaddrinfo
    for res in _socket.getaddrinfo(host, port, family, type, proto, flags):
socket.gaierror: [Errno 8] nodename nor servname provided, or not known

The above exception was the direct cause of the following exception:

Traceback (most recent call last):
  File "/usr/local/Caskroom/gcloud-cli/543.0.0/google-cloud-sdk/lib/third_party/urllib3/connectionpool.py", line 789, in urlopen
    response = self._make_request(
  File "/usr/local/Caskroom/gcloud-cli/543.0.0/google-cloud-sdk/lib/third_party/urllib3/connectionpool.py", line 490, in _make_request
    raise new_e
  File "/usr/local/Caskroom/gcloud-cli/543.0.0/google-cloud-sdk/lib/third_party/urllib3/connectionpool.py", line 466, in _make_request
    self._validate_conn(conn)
  File "/usr/local/Caskroom/gcloud-cli/543.0.0/google-cloud-sdk/lib/third_party/urllib3/connectionpool.py", line 1098, in _validate_conn
    conn.connect()
  File "/usr/local/Caskroom/gcloud-cli/543.0.0/google-cloud-sdk/lib/third_party/urllib3/connection.py", line 620, in connect
    self.sock = sock = self._new_conn()
  File "/usr/local/Caskroom/gcloud-cli/543.0.0/google-cloud-sdk/lib/third_party/urllib3/connection.py", line 206, in _new_conn
    raise NameResolutionError(self.host, self, e) from e
urllib3.exceptions.NameResolutionError: <urllib3.connection.HTTPSConnection object at 0x103abb4c0>: Failed to resolve 'dl.google.com' ([Errno 8] nodename nor servname provided, or not known)

The above exception was the direct cause of the following exception:

Traceback (most recent call last):
  File "/usr/local/Caskroom/gcloud-cli/543.0.0/google-cloud-sdk/lib/third_party/requests/adapters.py", line 667, in send
    resp = conn.urlopen(
  File "/usr/local/Caskroom/gcloud-cli/543.0.0/google-cloud-sdk/lib/third_party/urllib3/connectionpool.py", line 843, in urlopen
    retries = retries.increment(
  File "/usr/local/Caskroom/gcloud-cli/543.0.0/google-cloud-sdk/lib/third_party/urllib3/util/retry.py", line 520, in increment
    raise MaxRetryError(_pool, url, reason) from reason  # type: ignore[arg-type]
urllib3.exceptions.MaxRetryError: HTTPSConnectionPool(host='dl.google.com', port=443): Max retries exceeded with url: /dl/cloudsdk/channels/rapid/components-2.json (Caused by NameResolutionError("<urllib3.connection.HTTPSConnection object at 0x103abb4c0>: Failed to resolve 'dl.google.com' ([Errno 8] nodename nor servname provided, or not known)"))

During handling of the above exception, another exception occurred:

Traceback (most recent call last):
  File "/usr/local/Caskroom/gcloud-cli/543.0.0/google-cloud-sdk/lib/googlecloudsdk/gcloud_main.py", line 62, in UpdateCheck
    update_manager.UpdateManager.PerformUpdateCheck(command_path=command_path)
  File "/usr/local/Caskroom/gcloud-cli/543.0.0/google-cloud-sdk/lib/googlecloudsdk/core/updater/update_manager.py", line 315, in PerformUpdateCheck
    manager._PerformUpdateCheck(command_path, force=force)
  File "/usr/local/Caskroom/gcloud-cli/543.0.0/google-cloud-sdk/lib/googlecloudsdk/core/updater/update_manager.py", line 732, in _PerformUpdateCheck
    (_, diff) = self._GetStateAndDiff(
  File "/usr/local/Caskroom/gcloud-cli/543.0.0/google-cloud-sdk/lib/googlecloudsdk/core/updater/update_manager.py", line 686, in _GetStateAndDiff
    latest_snapshot = self._GetLatestSnapshot(version=version,
  File "/usr/local/Caskroom/gcloud-cli/543.0.0/google-cloud-sdk/lib/googlecloudsdk/core/updater/update_manager.py", line 669, in _GetLatestSnapshot
    return snapshots.ComponentSnapshot.FromURLs(
  File "/usr/local/Caskroom/gcloud-cli/543.0.0/google-cloud-sdk/lib/googlecloudsdk/core/updater/snapshots.py", line 175, in FromURLs
    data = [
  File "/usr/local/Caskroom/gcloud-cli/543.0.0/google-cloud-sdk/lib/googlecloudsdk/core/updater/snapshots.py", line 176, in <listcomp>
    (ComponentSnapshot._DictFromURL(
  File "/usr/local/Caskroom/gcloud-cli/543.0.0/google-cloud-sdk/lib/googlecloudsdk/core/updater/snapshots.py", line 200, in _DictFromURL
    response = installers.MakeRequest(url, command_path)
  File "/usr/local/Caskroom/gcloud-cli/543.0.0/google-cloud-sdk/lib/googlecloudsdk/core/updater/installers.py", line 115, in MakeRequest
    return _RawRequest(url, headers=headers, timeout=timeout)
  File "/usr/local/Caskroom/gcloud-cli/543.0.0/google-cloud-sdk/lib/googlecloudsdk/core/updater/installers.py", line 163, in _RawRequest
    return retryer.RetryOnException(
  File "/usr/local/Caskroom/gcloud-cli/543.0.0/google-cloud-sdk/lib/googlecloudsdk/core/util/retry.py", line 201, in RetryOnException
    exceptions.reraise(exc_info[1], tb=exc_info[2])
  File "/usr/local/Caskroom/gcloud-cli/543.0.0/google-cloud-sdk/lib/googlecloudsdk/core/exceptions.py", line 149, in reraise
    six.reraise(type(exc_value), exc_value, tb)
  File "/usr/local/Caskroom/gcloud-cli/543.0.0/google-cloud-sdk/lib/third_party/six/__init__.py", line 719, in reraise
    raise value
  File "/usr/local/Caskroom/gcloud-cli/543.0.0/google-cloud-sdk/lib/googlecloudsdk/core/util/retry.py", line 182, in TryFunc
    return func(*args, **kwargs), None
  File "/usr/local/Caskroom/gcloud-cli/543.0.0/google-cloud-sdk/lib/googlecloudsdk/core/updater/installers.py", line 196, in _ExecuteRequestAndRaiseExceptions
    response = requests_session.get(
  File "/usr/local/Caskroom/gcloud-cli/543.0.0/google-cloud-sdk/lib/third_party/requests/sessions.py", line 602, in get
    return self.request("GET", url, **kwargs)
  File "/usr/local/Caskroom/gcloud-cli/543.0.0/google-cloud-sdk/lib/googlecloudsdk/core/transport.py", line 281, in WrappedRequest
    response = orig_request(*modified_args, **modified_kwargs)
  File "/usr/local/Caskroom/gcloud-cli/543.0.0/google-cloud-sdk/lib/googlecloudsdk/core/requests.py", line 280, in WrappedRequest
    return orig_request_method(*args, **kwargs)
  File "/usr/local/Caskroom/gcloud-cli/543.0.0/google-cloud-sdk/lib/third_party/requests/sessions.py", line 589, in request
    resp = self.send(prep, **send_kwargs)
  File "/usr/local/Caskroom/gcloud-cli/543.0.0/google-cloud-sdk/lib/third_party/requests/sessions.py", line 703, in send
    r = adapter.send(request, **kwargs)
  File "/usr/local/Caskroom/gcloud-cli/543.0.0/google-cloud-sdk/lib/third_party/requests/adapters.py", line 700, in send
    raise ConnectionError(e, request=request)
requests.exceptions.ConnectionError: HTTPSConnectionPool(host='dl.google.com', port=443): Max retries exceeded with url: /dl/cloudsdk/channels/rapid/components-2.json (Caused by NameResolutionError("<urllib3.connection.HTTPSConnection object at 0x103abb4c0>: Failed to resolve 'dl.google.com' ([Errno 8] nodename nor servname provided, or not known)"))
